2024-04-24 Wed 00:03:01 __________  미국USD : 1,376.00원
2024-04-24 Wed 14:34:02 __________  미국USD : 1,370.30원
2024-04-24 Wed 14:35:02 __________  미국USD : 1,370.30원
2024-04-24 Wed 14:36:01 __________  미국USD : 1,370.50원
2024-04-24 Wed 14:37:01 __________  미국USD : 1,370.50원
2024-04-24 Wed 14:38:01 __________  미국USD : 1,370.50원
2024-04-24 Wed 14:39:01 __________  미국USD : 1,370.30원
2024-04-24 Wed 14:40:01 __________  미국USD : 1,370.30원
Traceback (most recent call last):
  File "/usr/lib/python3.10/urllib/request.py", line 1348, in do_open
    h.request(req.get_method(), req.selector, req.data, headers,
  File "/usr/lib/python3.10/http/client.py", line 1283, in request
    self._send_request(method, url, body, headers, encode_chunked)
  File "/usr/lib/python3.10/http/client.py", line 1329, in _send_request
    self.endheaders(body, encode_chunked=encode_chunked)
  File "/usr/lib/python3.10/http/client.py", line 1278, in endheaders
    self._send_output(message_body, encode_chunked=encode_chunked)
  File "/usr/lib/python3.10/http/client.py", line 1038, in _send_output
    self.send(msg)
  File "/usr/lib/python3.10/http/client.py", line 976, in send
    self.connect()
  File "/usr/lib/python3.10/http/client.py", line 1448, in connect
    super().connect()
  File "/usr/lib/python3.10/http/client.py", line 942, in connect
    self.sock = self._create_connection(
  File "/usr/lib/python3.10/socket.py", line 824, in create_connection
    for res in getaddrinfo(host, port, 0, SOCK_STREAM):
  File "/usr/lib/python3.10/socket.py", line 955, in getaddrinfo
    for res in _socket.getaddrinfo(host, port, family, type, proto, flags):
socket.gaierror: [Errno -3] Temporary failure in name resolution

During handling of the above exception, another exception occurred:

Traceback (most recent call last):
  File "/home/jiyeon/2024_bigdata/week2/3_market.py", line 10, in <module>
    res = req.urlopen(url).read()
  File "/usr/lib/python3.10/urllib/request.py", line 216, in urlopen
    return opener.open(url, data, timeout)
  File "/usr/lib/python3.10/urllib/request.py", line 519, in open
    response = self._open(req, data)
  File "/usr/lib/python3.10/urllib/request.py", line 536, in _open
    result = self._call_chain(self.handle_open, protocol, protocol +
  File "/usr/lib/python3.10/urllib/request.py", line 496, in _call_chain
    result = func(*args)
  File "/usr/lib/python3.10/urllib/request.py", line 1391, in https_open
    return self.do_open(http.client.HTTPSConnection, req,
  File "/usr/lib/python3.10/urllib/request.py", line 1351, in do_open
    raise URLError(err)
urllib.error.URLError: <urlopen error [Errno -3] Temporary failure in name resolution>
Traceback (most recent call last):
  File "/usr/lib/python3.10/urllib/request.py", line 1348, in do_open
    h.request(req.get_method(), req.selector, req.data, headers,
  File "/usr/lib/python3.10/http/client.py", line 1283, in request
    self._send_request(method, url, body, headers, encode_chunked)
  File "/usr/lib/python3.10/http/client.py", line 1329, in _send_request
    self.endheaders(body, encode_chunked=encode_chunked)
  File "/usr/lib/python3.10/http/client.py", line 1278, in endheaders
    self._send_output(message_body, encode_chunked=encode_chunked)
  File "/usr/lib/python3.10/http/client.py", line 1038, in _send_output
    self.send(msg)
  File "/usr/lib/python3.10/http/client.py", line 976, in send
    self.connect()
  File "/usr/lib/python3.10/http/client.py", line 1448, in connect
    super().connect()
  File "/usr/lib/python3.10/http/client.py", line 942, in connect
    self.sock = self._create_connection(
  File "/usr/lib/python3.10/socket.py", line 824, in create_connection
    for res in getaddrinfo(host, port, 0, SOCK_STREAM):
  File "/usr/lib/python3.10/socket.py", line 955, in getaddrinfo
    for res in _socket.getaddrinfo(host, port, family, type, proto, flags):
socket.gaierror: [Errno -3] Temporary failure in name resolution

During handling of the above exception, another exception occurred:

Traceback (most recent call last):
  File "/home/jiyeon/2024_bigdata/week2/3_market.py", line 10, in <module>
    res = req.urlopen(url).read()
  File "/usr/lib/python3.10/urllib/request.py", line 216, in urlopen
    return opener.open(url, data, timeout)
  File "/usr/lib/python3.10/urllib/request.py", line 519, in open
    response = self._open(req, data)
  File "/usr/lib/python3.10/urllib/request.py", line 536, in _open
    result = self._call_chain(self.handle_open, protocol, protocol +
  File "/usr/lib/python3.10/urllib/request.py", line 496, in _call_chain
    result = func(*args)
  File "/usr/lib/python3.10/urllib/request.py", line 1391, in https_open
    return self.do_open(http.client.HTTPSConnection, req,
  File "/usr/lib/python3.10/urllib/request.py", line 1351, in do_open
    raise URLError(err)
urllib.error.URLError: <urlopen error [Errno -3] Temporary failure in name resolution>
Traceback (most recent call last):
  File "/usr/lib/python3.10/urllib/request.py", line 1348, in do_open
    h.request(req.get_method(), req.selector, req.data, headers,
  File "/usr/lib/python3.10/http/client.py", line 1283, in request
    self._send_request(method, url, body, headers, encode_chunked)
  File "/usr/lib/python3.10/http/client.py", line 1329, in _send_request
    self.endheaders(body, encode_chunked=encode_chunked)
  File "/usr/lib/python3.10/http/client.py", line 1278, in endheaders
    self._send_output(message_body, encode_chunked=encode_chunked)
  File "/usr/lib/python3.10/http/client.py", line 1038, in _send_output
    self.send(msg)
  File "/usr/lib/python3.10/http/client.py", line 976, in send
    self.connect()
  File "/usr/lib/python3.10/http/client.py", line 1448, in connect
    super().connect()
  File "/usr/lib/python3.10/http/client.py", line 942, in connect
    self.sock = self._create_connection(
  File "/usr/lib/python3.10/socket.py", line 824, in create_connection
    for res in getaddrinfo(host, port, 0, SOCK_STREAM):
  File "/usr/lib/python3.10/socket.py", line 955, in getaddrinfo
    for res in _socket.getaddrinfo(host, port, family, type, proto, flags):
socket.gaierror: [Errno -3] Temporary failure in name resolution

During handling of the above exception, another exception occurred:

Traceback (most recent call last):
  File "/home/jiyeon/2024_bigdata/week2/3_market.py", line 10, in <module>
    res = req.urlopen(url).read()
  File "/usr/lib/python3.10/urllib/request.py", line 216, in urlopen
    return opener.open(url, data, timeout)
  File "/usr/lib/python3.10/urllib/request.py", line 519, in open
    response = self._open(req, data)
  File "/usr/lib/python3.10/urllib/request.py", line 536, in _open
    result = self._call_chain(self.handle_open, protocol, protocol +
  File "/usr/lib/python3.10/urllib/request.py", line 496, in _call_chain
    result = func(*args)
  File "/usr/lib/python3.10/urllib/request.py", line 1391, in https_open
    return self.do_open(http.client.HTTPSConnection, req,
  File "/usr/lib/python3.10/urllib/request.py", line 1351, in do_open
    raise URLError(err)
urllib.error.URLError: <urlopen error [Errno -3] Temporary failure in name resolution>
Traceback (most recent call last):
  File "/usr/lib/python3.10/urllib/request.py", line 1348, in do_open
    h.request(req.get_method(), req.selector, req.data, headers,
  File "/usr/lib/python3.10/http/client.py", line 1283, in request
    self._send_request(method, url, body, headers, encode_chunked)
  File "/usr/lib/python3.10/http/client.py", line 1329, in _send_request
    self.endheaders(body, encode_chunked=encode_chunked)
  File "/usr/lib/python3.10/http/client.py", line 1278, in endheaders
    self._send_output(message_body, encode_chunked=encode_chunked)
  File "/usr/lib/python3.10/http/client.py", line 1038, in _send_output
    self.send(msg)
  File "/usr/lib/python3.10/http/client.py", line 976, in send
    self.connect()
  File "/usr/lib/python3.10/http/client.py", line 1448, in connect
    super().connect()
  File "/usr/lib/python3.10/http/client.py", line 942, in connect
    self.sock = self._create_connection(
  File "/usr/lib/python3.10/socket.py", line 824, in create_connection
    for res in getaddrinfo(host, port, 0, SOCK_STREAM):
  File "/usr/lib/python3.10/socket.py", line 955, in getaddrinfo
    for res in _socket.getaddrinfo(host, port, family, type, proto, flags):
socket.gaierror: [Errno -3] Temporary failure in name resolution

During handling of the above exception, another exception occurred:

Traceback (most recent call last):
  File "/home/jiyeon/2024_bigdata/week2/3_market.py", line 10, in <module>
    res = req.urlopen(url).read()
  File "/usr/lib/python3.10/urllib/request.py", line 216, in urlopen
    return opener.open(url, data, timeout)
  File "/usr/lib/python3.10/urllib/request.py", line 519, in open
    response = self._open(req, data)
  File "/usr/lib/python3.10/urllib/request.py", line 536, in _open
    result = self._call_chain(self.handle_open, protocol, protocol +
  File "/usr/lib/python3.10/urllib/request.py", line 496, in _call_chain
    result = func(*args)
  File "/usr/lib/python3.10/urllib/request.py", line 1391, in https_open
    return self.do_open(http.client.HTTPSConnection, req,
  File "/usr/lib/python3.10/urllib/request.py", line 1351, in do_open
    raise URLError(err)
urllib.error.URLError: <urlopen error [Errno -3] Temporary failure in name resolution>
2024-04-24 Wed 14:51:01 __________  미국USD : 1,369.90원
2024-04-24 Wed 14:52:02 __________  미국USD : 1,369.80원
2024-04-24 Wed 14:53:01 __________  미국USD : 1,369.80원
2024-04-24 Wed 14:54:02 __________  미국USD : 1,369.80원
2024-04-24 Wed 14:55:02 __________  미국USD : 1,369.80원
2024-04-29 Mon 20:28:01 __________  미국USD : 1,377.50원
2024-04-29 Mon 20:29:01 __________  미국USD : 1,377.50원
2024-04-29 Mon 20:30:02 __________  미국USD : 1,377.50원
2024-04-29 Mon 20:31:01 __________  미국USD : 1,377.50원
2024-04-29 Mon 20:32:01 __________  미국USD : 1,377.50원
2024-04-29 Mon 20:33:01 __________  미국USD : 1,377.50원
2024-04-29 Mon 20:34:01 __________  미국USD : 1,377.50원
2024-04-29 Mon 20:36:02 __________  미국USD : 1,377.50원
2024-04-29 Mon 20:37:01 __________  미국USD : 1,377.50원
2024-04-29 Mon 20:38:01 __________  미국USD : 1,377.50원
                                                            2024-04-29 Mon 20:41:02 __________  미국USD : 1,377.50원
2024-04-29 Mon 20:45:03 __________  미국USD : 1,377.50원
2024-04-29 Mon 20:46:01 __________  미국USD : 1,377.50원
2024-04-29 Mon 20:47:01 __________  미국USD : 1,377.50원
2024-04-29 Mon 20:48:01 __________  미국USD : 1,377.50원
2024-04-29 Mon 20:49:01 __________  미국USD : 1,377.50원
2024-04-29 Mon 20:50:01 __________  미국USD : 1,377.50원
2024-04-29 Mon 20:51:02 __________  미국USD : 1,377.50원
2024-04-29 Mon 20:52:01 __________  미국USD : 1,377.50원
2024-04-29 Mon 20:53:02 __________  미국USD : 1,377.50원
2024-04-29 Mon 20:54:01 __________  미국USD : 1,377.50원
2024-04-29 Mon 20:55:01 __________  미국USD : 1,377.50원
2024-04-29 Mon 20:56:01 __________  미국USD : 1,377.50원
2024-04-29 Mon 20:57:01 __________  미국USD : 1,377.50원
2024-04-29 Mon 20:58:01 __________  미국USD : 1,377.50원
2024-04-29 Mon 20:59:02 __________  미국USD : 1,377.50원
2024-04-29 Mon 21:00:01 __________  미국USD : 1,378.50원
2024-04-29 Mon 21:01:02 __________  미국USD : 1,378.50원
2024-04-29 Mon 21:02:01 __________  미국USD : 1,378.50원
2024-04-29 Mon 21:03:02 __________  미국USD : 1,378.50원
2024-04-29 Mon 21:04:01 __________  미국USD : 1,378.50원
2024-04-29 Mon 21:05:02 __________  미국USD : 1,378.50원
2024-04-29 Mon 21:06:02 __________  미국USD : 1,378.50원
2024-04-29 Mon 21:07:01 __________  미국USD : 1,378.50원
2024-04-29 Mon 21:08:01 __________  미국USD : 1,378.50원
2024-04-29 Mon 21:09:01 __________  미국USD : 1,378.50원
2024-04-29 Mon 21:10:01 __________  미국USD : 1,378.50원
2024-04-29 Mon 21:11:01 __________  미국USD : 1,378.50원
2024-04-29 Mon 21:12:02 __________  미국USD : 1,378.50원
2024-04-29 Mon 21:13:01 __________  미국USD : 1,378.50원
2024-04-29 Mon 21:14:02 __________  미국USD : 1,378.50원
2024-04-29 Mon 21:15:01 __________  미국USD : 1,378.50원
2024-04-29 Mon 21:16:02 __________  미국USD : 1,378.50원
2024-04-29 Mon 21:17:01 __________  미국USD : 1,378.50원
2024-04-29 Mon 21:18:01 __________  미국USD : 1,378.50원
2024-04-29 Mon 21:19:01 __________  미국USD : 1,378.50원
